[2024-02-29T07:57:55.309+0000] {taskinstance.py:1957} INFO - Dependencies all met for dep_context=non-requeueable deps ti=<TaskInstance: weather_api_dag.get_weather_data scheduled__2024-02-07T00:00:00+00:00 [queued]>
[2024-02-29T07:57:55.327+0000] {taskinstance.py:1957} INFO - Dependencies all met for dep_context=requeueable deps ti=<TaskInstance: weather_api_dag.get_weather_data scheduled__2024-02-07T00:00:00+00:00 [queued]>
[2024-02-29T07:57:55.327+0000] {taskinstance.py:2171} INFO - Starting attempt 1 of 1
[2024-02-29T07:57:55.486+0000] {taskinstance.py:2192} INFO - Executing <Task(PythonOperator): get_weather_data> on 2024-02-07 00:00:00+00:00
[2024-02-29T07:57:55.530+0000] {standard_task_runner.py:60} INFO - Started process 3133 to run task
[2024-02-29T07:57:55.541+0000] {standard_task_runner.py:87} INFO - Running: ['***', 'tasks', 'run', 'weather_api_dag', 'get_weather_data', 'scheduled__2024-02-07T00:00:00+00:00', '--job-id', '269', '--raw', '--subdir', 'DAGS_FOLDER/weather_api_dag.py', '--cfg-path', '/tmp/tmpvhvpfl53']
[2024-02-29T07:57:55.544+0000] {standard_task_runner.py:88} INFO - Job 269: Subtask get_weather_data
[2024-02-29T07:57:55.680+0000] {task_command.py:423} INFO - Running <TaskInstance: weather_api_dag.get_weather_data scheduled__2024-02-07T00:00:00+00:00 [running]> on host 70f5ffd40a68
[2024-02-29T07:57:55.940+0000] {taskinstance.py:2481} INFO - Exporting env vars: AIRFLOW_CTX_DAG_OWNER='***' AIRFLOW_CTX_DAG_ID='weather_api_dag' AIRFLOW_CTX_TASK_ID='get_weather_data' AIRFLOW_CTX_EXECUTION_DATE='2024-02-07T00:00:00+00:00' AIRFLOW_CTX_TRY_NUMBER='1' AIRFLOW_CTX_DAG_RUN_ID='scheduled__2024-02-07T00:00:00+00:00'
[2024-02-29T07:57:55.944+0000] {taskinstance.py:2699} ERROR - Task failed with exception
Traceback (most recent call last):
  File "/home/airflow/.local/lib/python3.8/site-packages/airflow/models/taskinstance.py", line 433, in _execute_task
    result = execute_callable(context=context, **execute_callable_kwargs)
  File "/home/airflow/.local/lib/python3.8/site-packages/airflow/operators/python.py", line 199, in execute
    return_value = self.execute_callable()
  File "/home/airflow/.local/lib/python3.8/site-packages/airflow/operators/python.py", line 216, in execute_callable
    return self.python_callable(*self.op_args, **self.op_kwargs)
  File "/opt/airflow/dags/weather_api_dag.py", line 18, in _get_weather_data
    }
NameError: name 'requests' is not defined
[2024-02-29T07:57:55.970+0000] {taskinstance.py:1138} INFO - Marking task as FAILED. dag_id=weather_api_dag, task_id=get_weather_data, execution_date=20240207T000000, start_date=20240229T075755, end_date=20240229T075755
[2024-02-29T07:57:55.999+0000] {standard_task_runner.py:107} ERROR - Failed to execute job 269 for task get_weather_data (name 'requests' is not defined; 3133)
[2024-02-29T07:57:56.043+0000] {local_task_job_runner.py:234} INFO - Task exited with return code 1
[2024-02-29T07:57:56.088+0000] {taskinstance.py:3281} INFO - 0 downstream tasks scheduled from follow-on schedule check
